File: xrd/200831/RT_0d1M.ras
*RAS_DATA_START
*RAS_HEADER_START
*CORR_POS_DB_NAME "Correct_20190620"
*CORR_POS_GONIO_RADIUS ""
*CORR_POS_NODE_INDEX01 ""
*CORR_POS_NODE_INDEX02 ""
*CORR_POS_NODE_INDEX03 ""
*CORR_POS_NODE_INDEX04 ""
*CORR_POS_NODE_INDEX05 ""
*CORR_POS_NODE_INDEX06 ""
*CORR_POS_NODE_INDEX07 ""
*CORR_POS_NODE_INDEX08 ""
*CORR_POS_NODE_INDEX09 ""
*CORR_POS_NODE_INDEX10 ""
*CORR_POS_NODE_INDEX11 ""
*CORR_POS_NODE_LABEL01 "Si(111)"
*CORR_POS_NODE_LABEL02 "Si(220)"
*CORR_POS_NODE_LABEL03 "Si(311)"
*CORR_POS_NODE_LABEL04 "Si(400)"
*CORR_POS_NODE_LABEL05 "Si(331)"
*CORR_POS_NODE_LABEL06 "Si(422)"
*CORR_POS_NODE_LABEL07 "Si(511)"
*CORR_POS_NODE_LABEL08 "Si(440)"
*CORR_POS_NODE_LABEL09 "Si(531)"
*CORR_POS_NODE_LABEL10 "Si(620)"
*CORR_POS_NODE_LABEL11 "Si(533)"
*CORR_POS_NODE_POS_CALC01 "28.4005"
*CORR_POS_NODE_POS_CALC02 "47.2634"
*CORR_POS_NODE_POS_CALC03 "56.0825"
*CORR_POS_NODE_POS_CALC04 "69.0892"
*CORR_POS_NODE_POS_CALC05 "76.335"
*CORR_POS_NODE_POS_CALC06 "87.989"
*CORR_POS_NODE_POS_CALC07 "94.9117"
*CORR_POS_NODE_POS_CALC08 "106.669"
*CORR_POS_NODE_POS_CALC09 "114.054"
*CORR_POS_NODE_POS_CALC10 "127.509"
*CORR_POS_NODE_POS_CALC11 "136.859"
*CORR_POS_NODE_POS_MEAS01 "28.3879"
*CORR_POS_NODE_POS_MEAS02 "47.243"
*CORR_POS_NODE_POS_MEAS03 "56.0511"
*CORR_POS_NODE_POS_MEAS04 "69.0708"
*CORR_POS_NODE_POS_MEAS05 "76.3178"
*CORR_POS_NODE_POS_MEAS06 "87.9728"
*CORR_POS_NODE_POS_MEAS07 "94.8964"
*CORR_POS_NODE_POS_MEAS08 "106.655"
*CORR_POS_NODE_POS_MEAS09 "114.033"
*CORR_POS_NODE_POS_MEAS10 "127.497"
*CORR_POS_NODE_POS_MEAS11 "136.844"
*CORR_POS_OPT_ATTR "集中法"
*CORR_POS_PARAM_MU ""
*CORR_POS_PARAM_PL ""
*CORR_POS_SEMODEL_TYPE "0"
*CORR_POS_STANDARD_TYPE ""
*CORR_POS_VALUE_ANALYZER "None"
*CORR_POS_VALUE_CMONO "None_None"
*CORR_POS_VALUE_IMONO "None"
*CORR_POS_VALUE_IS "1.250deg"
*CORR_POS_VALUE_ISL "10.0mm"
*CORR_POS_VALUE_ISOLLER "2.5deg"
*CORR_POS_VALUE_RS1 "13.0mm"
*CORR_POS_VALUE_RS2 "13.0mm"
*CORR_POS_VALUE_RSOLLER "2.5deg"
*CORR_POS_XG_FOCUS_L ""
*CORR_POS_XG_WAVE_TYPE ""
*CORR_POS_XG_WAVE_VALUE ""
*DISP_FMT_X "%.2f"
*DISP_FMT_Y "%.0f"
*DISP_FULLSCALE "6185.0000000000"
*DISP_LINE_COLOR "255.0000000000"
*DISP_LINE_STYLE "0.0000000000"
*DISP_LINE_WIDTH "0.2500000000"
*DISP_NOTE "測定データ-4"
*DISP_OFFSET_Y "0.0000000000"
*DISP_PEAKSEARCH_UNIT_Y "cps"
*DISP_RANGE_BOTTOM "0.0000000000"
*DISP_RANGE_LEFT "5.0000000000"
*DISP_RANGE_LOGCUTOFF "0.0100000000"
*DISP_RANGE_RIGHT "60.0000000000"
*DISP_RANGE_TOP "6185.0000000000"
*DISP_SCALE_MODE_Y "0.0000000000"
*DISP_TAB_NAME "2θ/θ"
*DISP_TITLE_Y "強度"
*DISP_UNIT_Y "cps"
*DISP_WINDOW_NAME "MSG_MACROENGINE"
*FILE_COMMENT " "
*FILE_MD5 ""
*FILE_MEMO " "
*FILE_OPERATOR "administrator"
*FILE_PART_ID "MEAS_PBEA_00223"
*FILE_SAMPLE " "
*FILE_TYPE "RAS_RAW"
*FILE_USERGROUP "システムマネージャ"
*FILE_VERSION "1.0000000000"
*HW_ATTACHMENT_ID "ATT1025"
*HW_ATTACHMENT_NAME "標準試料台|Standard Sample Stage"
*HW_COUNTER_ID-0 "CUT0025"
*HW_COUNTER_ID-1 "CUT0020"
*HW_COUNTER_ID-2 "CUT0020"
*HW_COUNTER_ID-3 "CMC0021"
*HW_COUNTER_NAME-0 "D/teX Ultra2|D/teX Ultra2"
*HW_COUNTER_NAME-1 "None|None"
*HW_COUNTER_NAME-2 "None|None"
*HW_COUNTER_NAME-3 "検出器モノクロメータ|Detector monochromator"
*HW_COUNTER_SELECT_NAME "D/teX Ultra2|D/teX Ultra2"
*HW_GONIOMETER_ID "GON0070"
*HW_GONIOMETER_NAME "MiniFlex 300/600|MiniFlex 300/600"
*HW_GONIOMETER_RADIUS-0 "79.0"
*HW_GONIOMETER_RADIUS-1 "91.5"
*HW_GONIOMETER_RADIUS-2 "150.0"
*HW_GONIOMETER_RADIUS-3 "0"
*HW_GONIOMETER_RADIUS-4 "92.7"
*HW_GONIOMETER_RADIUS-5 "139.3"
*HW_GONIOMETER_RADIUS-6 "46.6"
*HW_GONIOMETER_RADIUS-7 "150.0"
*HW_I_OPT_ID-0 "ISL0021"
*HW_I_OPT_ID-1 "ISO0021"
*HW_I_OPT_NAME-0 "発散スリット|Divergence slit"
*HW_I_OPT_NAME-1 "入射平行スリット|Incident parallel slit"
*HW_R_ATTENUATER_AUTOMODE "0"
*HW_R_OPT_ID-0 "RSS0021"
*HW_R_OPT_ID-1 "RSO0021"
*HW_R_OPT_ID-2 "RRS0021"
*HW_R_OPT_NAME-0 "散乱スリット|Scattering slit"
*HW_R_OPT_NAME-1 "受光平行スリット|Receiving soller slit"
*HW_R_OPT_NAME-2 "受光スリット|Receiving slit"
*HW_SAMPLE_HOLDER_ID "SMP0000"
*HW_SAMPLE_HOLDER_NAME "無し|None"
*HW_XG_CURRENT_MAX "15"
*HW_XG_CURRENT_MIN "2"
*HW_XG_CURRENT_RESOLUTION "1"
*HW_XG_CURRENT_UNIT "mA"
*HW_XG_FOCUS "1mm x 10mm"
*HW_XG_FOCUS_TYPE "Normal"
*HW_XG_ID "1060"
*HW_XG_NAME "300W/600W 封入管-B|300W/600W Sealed tube-B"
*HW_XG_TARGET_ATOMIC_NUMBER "29.0000000000"
*HW_XG_TARGET_NAME "Cu"
*HW_XG_TYPE "Hermetic"
*HW_XG_VOLTAGE_MAX "40"
*HW_XG_VOLTAGE_MIN "20"
*HW_XG_VOLTAGE_RESOLUTION "1"
*HW_XG_VOLTAGE_UNIT "kV"
*HW_XG_WATT_MAX "1"
*HW_XG_WATT_UNIT "kW"
*HW_XG_WAVE_LENGTH_ALPHA1 "1.540593"
*HW_XG_WAVE_LENGTH_ALPHA2 "1.544414"
*HW_XG_WAVE_LENGTH_BETA "1.392250"
*MEAS_COND_AXIS_NAME-0 "2θ/θ"
*MEAS_COND_AXIS_NAME-1 "Soller(inc.)"
*MEAS_COND_AXIS_NAME-2 "IHS"
*MEAS_COND_AXIS_NAME-3 "DS"
*MEAS_COND_AXIS_NAME-4 "SS"
*MEAS_COND_AXIS_NAME-5 "Soller(rec.)"
*MEAS_COND_AXIS_NAME-6 "RS"
*MEAS_COND_AXIS_NAME-7 "フィルター"
*MEAS_COND_AXIS_NAME-8 "モノクロメータ"
*MEAS_COND_AXIS_NAME-9 "PHA"
*MEAS_COND_AXIS_NAME_INTERNAL-0 "TwoThetaTheta"
*MEAS_COND_AXIS_NAME_INTERNAL-1 "IncidentSollerSlit"
*MEAS_COND_AXIS_NAME_INTERNAL-2 "IncidentAxdSlit"
*MEAS_COND_AXIS_NAME_INTERNAL-3 "IncidentSlitBox"
*MEAS_COND_AXIS_NAME_INTERNAL-4 "ReceivingSlitBox1"
*MEAS_COND_AXIS_NAME_INTERNAL-5 "ReceivingSollerSlit"
*MEAS_COND_AXIS_NAME_INTERNAL-6 "ReceivingSlitBox2"
*MEAS_COND_AXIS_NAME_INTERNAL-7 "Filter"
*MEAS_COND_AXIS_NAME_INTERNAL-8 "CounterMonochromator"
*MEAS_COND_AXIS_NAME_INTERNAL-9 "PHA"
*MEAS_COND_AXIS_NAME_MAGICNO-0 "268632064.0000000000"
*MEAS_COND_AXIS_NAME_MAGICNO-1 "20971521.0000000000"
*MEAS_COND_AXIS_NAME_MAGICNO-2 "22020097.0000000000"
*MEAS_COND_AXIS_NAME_MAGICNO-3 "22020097.0000000000"
*MEAS_COND_AXIS_NAME_MAGICNO-4 "23068673.0000000000"
*MEAS_COND_AXIS_NAME_MAGICNO-5 "20971521.0000000000"
*MEAS_COND_AXIS_NAME_MAGICNO-6 "23068673.0000000000"
*MEAS_COND_AXIS_NAME_MAGICNO-7 "20971521.0000000000"
*MEAS_COND_AXIS_NAME_MAGICNO-8 "20971521.0000000000"
*MEAS_COND_AXIS_NAME_MAGICNO-9 "0.0000000000"
*MEAS_COND_AXIS_OFFSET-0 "0.0000000000"
*MEAS_COND_AXIS_OFFSET-1 "-"
*MEAS_COND_AXIS_OFFSET-2 "-"
*MEAS_COND_AXIS_OFFSET-3 "-"
*MEAS_COND_AXIS_OFFSET-4 "-"
*MEAS_COND_AXIS_OFFSET-5 "-"
*MEAS_COND_AXIS_OFFSET-6 "-"
*MEAS_COND_AXIS_OFFSET-7 "-"
*MEAS_COND_AXIS_OFFSET-8 "-"
*MEAS_COND_AXIS_OFFSET-9 "-"
*MEAS_COND_AXIS_POSITION-0 "12.0000000000"
*MEAS_COND_AXIS_POSITION-1 "2.5deg"
*MEAS_COND_AXIS_POSITION-2 "10.0mm"
*MEAS_COND_AXIS_POSITION-3 "1.250deg"
*MEAS_COND_AXIS_POSITION-4 "8.0mm"
*MEAS_COND_AXIS_POSITION-5 "2.5deg"
*MEAS_COND_AXIS_POSITION-6 "13.0mm(Open)"
*MEAS_COND_AXIS_POSITION-7 "K-beta(x1.5)"
*MEAS_COND_AXIS_POSITION-8 "None"
*MEAS_COND_AXIS_POSITION-9 "36.0000000000"
*MEAS_COND_AXIS_UNIT-0 "deg"
*MEAS_COND_AXIS_UNIT-1 ""
*MEAS_COND_AXIS_UNIT-2 ""
*MEAS_COND_AXIS_UNIT-3 ""
*MEAS_COND_AXIS_UNIT-4 ""
*MEAS_COND_AXIS_UNIT-5 ""
*MEAS_COND_AXIS_UNIT-6 ""
*MEAS_COND_AXIS_UNIT-7 ""
*MEAS_COND_AXIS_UNIT-8 ""
*MEAS_COND_AXIS_UNIT-9 "div"
*MEAS_COND_CORRECTION_SLIT_COUNTERMONO "None"
*MEAS_COND_CORRECTION_SLIT_DS "1.250deg"
*MEAS_COND_CORRECTION_SLIT_FILTER "None"
*MEAS_COND_CORRECTION_SLIT_IHS "10.0mm"
*MEAS_COND_CORRECTION_SLIT_RS "13.0mm"
*MEAS_COND_CORRECTION_SLIT_SOLLER_INC "2.5deg"
*MEAS_COND_CORRECTION_SLIT_SOLLER_REC "2.5deg"
*MEAS_COND_CORRECTION_SLIT_SS "8.0mm"
*MEAS_COND_COUNTER_CNTLOSS_CORR "0.0000000000"
*MEAS_COND_COUNTER_PHABASE "36.0000000000"
*MEAS_COND_COUNTER_PHAWINDOW "16.0000000000"
*MEAS_COND_COUNTER_PHA_UNIT "div"
*MEAS_COND_COUNTER_TAUDIFF "0.2500000000"
*MEAS_COND_COUNTER_TAUINT "0.7500000000"
*MEAS_COND_IRRADIATION_MODE "OFF"
*MEAS_COND_IRRADIATION_WIDTH ""
*MEAS_COND_OPT_ATTR " "
*MEAS_COND_OPT_NAME ""
*MEAS_COND_UNSYMMETRIC_MODE "OFF"
*MEAS_COND_XG_CURRENT "15.0000000000"
*MEAS_COND_XG_VOLTAGE "40.0000000000"
*MEAS_COND_XG_WAVE_TYPE "Ka"
*MEAS_DATA_COUNT "2751.0000000000"
*MEAS_SCAN_AXIS_X "2θ/θ"
*MEAS_SCAN_AXIS_X_INTERNAL "TwoThetaTheta"
*MEAS_SCAN_END_TIME "08/31/20 15:01:05"
*MEAS_SCAN_MODE "CONTINUOUS"
*MEAS_SCAN_MONITOR "0"
*MEAS_SCAN_RESOLUTION_X "0.0025"
*MEAS_SCAN_SPEED "5.000000"
*MEAS_SCAN_SPEED_UNIT "deg/min"
*MEAS_SCAN_SPEED_USER "5.000000"
*MEAS_SCAN_START "5.0000000000"
*MEAS_SCAN_START_TIME "08/31/20 14:48:47"
*MEAS_SCAN_STEP "0.0200000000"
*MEAS_SCAN_STOP "60.0000000000"
*MEAS_SCAN_UNIT_X "deg"
*MEAS_SCAN_UNIT_Y "counts"
*SLIT_SYSTEM "0"
*RAS_HEADER_END
*RAS_INT_START
5.0000 448.0000 1.0000
5.0400 482.0000 1.0000
5.0800 507.0000 1.0000
5.1200 507.0000 1.0000
5.1600 507.0000 1.0000
5.2000 481.0000 1.0000
5.2400 563.0000 1.0000
5.2800 530.0000 1.0000
5.3200 463.0000 1.0000
5.3600 449.0000 1.0000
5.4000 495.0000 1.0000
5.4400 463.0000 1.0000
5.4800 504.0000 1.0000
5.5200 450.0000 1.0000
5.5600 484.0000 1.0000
5.6000 487.0000 1.0000
5.6400 487.0000 1.0000
5.6800 483.0000 1.0000
5.7200 552.0000 1.0000
5.7600 464.0000 1.0000
5.8000 512.0000 1.0000
5.8400 595.0000 1.0000
5.8800 511.0000 1.0000
5.9200 473.0000 1.0000
5.9600 545.0000 1.0000
6.0000 486.0000 1.0000
6.0400 560.0000 1.0000
6.0800 491.0000 1.0000
6.1200 513.0000 1.0000
6.1600 440.0000 1.0000
6.2000 494.0000 1.0000
6.2400 464.0000 1.0000
6.2800 461.0000 1.0000
6.3200 511.0000 1.0000
6.3600 532.0000 1.0000
6.4000 490.0000 1.0000
6.4400 470.0000 1.0000
6.4800 496.0000 1.0000
6.5200 510.0000 1.0000
6.5600 527.0000 1.0000
6.6000 495.0000 1.0000
6.6400 504.0000 1.0000
6.6800 500.0000 1.0000
6.7200 484.0000 1.0000
6.7600 481.0000 1.0000
6.8000 519.0000 1.0000
6.8400 472.0000 1.0000
6.8800 527.0000 1.0000
6.9200 467.0000 1.0000
6.9600 494.0000 1.0000
7.0000 504.0000 1.0000
7.0400 507.0000 1.0000
7.0800 493.0000 1.0000
7.1200 504.0000 1.0000
7.1600 480.0000 1.0000
7.2000 532.0000 1.0000
7.2400 537.0000 1.0000
7.2800 464.0000 1.0000
7.3200 485.0000 1.0000
7.3600 558.0000 1.0000
7.4000 505.0000 1.0000
7.4400 492.0000 1.0000
7.4800 489.0000 1.0000
7.5200 489.0000 1.0000
7.5600 432.0000 1.0000
7.6000 460.0000 1.0000
7.6400 455.0000 1.0000
7.6800 528.0000 1.0000
7.7200 462.0000 1.0000
7.7600 457.0000 1.0000
7.8000 501.0000 1.0000
7.8400 491.0000 1.0000
7.8800 484.0000 1.0000
7.9200 495.0000 1.0000
7.9600 552.0000 1.0000
8.0000 509.0000 1.0000
8.0400 500.0000 1.0000
8.0800 467.0000 1.0000
8.1200 472.0000 1.0000
8.1600 527.0000 1.0000
8.2000 540.0000 1.0000
8.2400 546.0000 1.0000
8.2800 478.0000 1.0000
8.3200 503.0000 1.0000
8.3600 541.0000 1.0000
8.4000 512.0000 1.0000
8.4400 478.0000 1.0000
8.4800 502.0000 1.0000
8.5200 500.0000 1.0000
8.5600 467.0000 1.0000
8.6000 508.0000 1.0000
8.6400 564.0000 1.0000
8.6800 491.0000 1.0000
8.7200 508.0000 1.0000
8.7600 525.0000 1.0000
8.8000 539.0000 1.0000
8.8400 495.0000 1.0000
8.8800 492.0000 1.0000
8.9200 526.0000 1.0000
8.9600 538.0000 1.0000
9.0000 540.0000 1.0000
9.0400 502.0000 1.0000
9.0800 529.0000 1.0000
9.1200 498.0000 1.0000
9.1600 477.0000 1.0000
9.2000 485.0000 1.0000
9.2400 566.0000 1.0000
9.2800 520.0000 1.0000
9.3200 549.0000 1.0000
9.3600 503.0000 1.0000
9.4000 537.0000 1.0000
9.4400 533.0000 1.0000
9.4800 536.0000 1.0000
9.5200 550.0000 1.0000
9.5600 561.0000 1.0000
9.6000 518.0000 1.0000
9.6400 506.0000 1.0000
9.6800 564.0000 1.0000
9.7200 556.0000 1.0000
9.7600 553.0000 1.0000
9.8000 568.0000 1.0000
9.8400 576.0000 1.0000
9.8800 552.0000 1.0000
9.9200 563.0000 1.0000
9.9600 576.0000 1.0000
10.0000 593.0000 1.0000
10.0400 555.0000 1.0000
10.0800 558.0000 1.0000
10.1200 565.0000 1.0000
10.1600 611.0000 1.0000
10.2000 592.0000 1.0000
10.2400 588.0000 1.0000
10.2800 629.0000 1.0000
10.3200 607.0000 1.0000
10.3600 586.0000 1.0000
10.4000 631.0000 1.0000
10.4400 627.0000 1.0000
10.4800 598.0000 1.0000
10.5200 627.0000 1.0000
10.5600 607.0000 1.0000
10.6000 605.0000 1.0000
10.6400 657.0000 1.0000
10.6800 639.0000 1.0000
10.7200 664.0000 1.0000
10.7600 634.0000 1.0000
10.8000 672.0000 1.0000
10.8400 664.0000 1.0000
10.8800 677.0000 1.0000
10.9200 676.0000 1.0000
10.9600 681.0000 1.0000
11.0000 702.0000 1.0000
11.0400 728.0000 1.0000
11.0800 692.0000 1.0000
11.1200 726.0000 1.0000
11.1600 722.0000 1.0000
11.2000 696.0000 1.0000
11.2400 735.0000 1.0000
11.2800 772.0000 1.0000
11.3200 745.0000 1.0000
11.3600 751.0000 1.0000
11.4000 755.0000 1.0000
11.4400 770.0000 1.0000
11.4800 777.0000 1.0000
11.5200 745.0000 1.0000
11.5600 783.0000 1.0000
11.6000 779.0000 1.0000
11.6400 781.0000 1.0000
11.6800 746.0000 1.0000
11.7200 796.0000 1.0000
11.7600 803.0000 1.0000
11.8000 824.0000 1.0000
11.8400 807.0000 1.0000
11.8800 809.0000 1.0000
11.9200 828.0000 1.0000
11.9600 829.0000 1.0000
12.0000 795.0000 1.0000
12.0400 789.0000 1.0000
12.0800 810.0000 1.0000
12.1200 792.0000 1.0000
12.1600 826.0000 1.0000
12.2000 822.0000 1.0000
12.2400 776.0000 1.0000
12.2800 818.0000 1.0000
12.3200 817.0000 1.0000
12.3600 782.0000 1.0000
12.4000 810.0000 1.0000
12.4400 807.0000 1.0000
12.4800 820.0000 1.0000
12.5200 808.0000 1.0000
12.5600 751.0000 1.0000
12.6000 779.0000 1.0000
12.6400 799.0000 1.0000
12.6800 736.0000 1.0000
12.7200 754.0000 1.0000
12.7600 770.0000 1.0000
12.8000 723.0000 1.0000
12.8400 736.0000 1.0000
12.8800 763.0000 1.0000
12.9200 770.0000 1.0000
12.9600 742.0000 1.0000
13.0000 740.0000 1.0000
13.0400 745.0000 1.0000
13.0800 682.0000 1.0000
13.1200 682.0000 1.0000
13.1600 711.0000 1.0000
13.2000 682.0000 1.0000
13.2400 678.0000 1.0000
13.2800 696.0000 1.0000
13.3200 655.0000 1.0000
13.3600 728.0000 1.0000
13.4000 672.0000 1.0000
13.4400 667.0000 1.0000
13.4800 648.0000 1.0000
13.5200 677.0000 1.0000
13.5600 673.0000 1.0000
13.6000 633.0000 1.0000
13.6400 643.0000 1.0000
13.6800 624.0000 1.0000
13.7200 626.0000 1.0000
13.7600 650.0000 1.0000
13.8000 663.0000 1.0000
13.8400 673.0000 1.0000
13.8800 649.0000 1.0000
13.9200 643.0000 1.0000
13.9600 637.0000 1.0000
14.0000 618.0000 1.0000
14.0400 604.0000 1.0000
14.0800 611.0000 1.0000
14.1200 616.0000 1.0000
14.1600 584.0000 1.0000
14.2000 633.0000 1.0000
14.2400 601.0000 1.0000
14.2800 615.0000 1.0000
14.3200 606.0000 1.0000
14.3600 643.0000 1.0000
14.4000 617.0000 1.0000
14.4400 625.0000 1.0000
14.4800 610.0000 1.0000
14.5200 556.0000 1.0000
14.5600 603.0000 1.0000
14.6000 595.0000 1.0000
14.6400 569.0000 1.0000
14.6800 607.0000 1.0000
14.7200 608.0000 1.0000
14.7600 588.0000 1.0000
14.8000 605.0000 1.0000
14.8400 595.0000 1.0000
14.8800 614.0000 1.0000
14.9200 612.0000 1.0000
14.9600 608.0000 1.0000
15.0000 587.0000 1.0000
15.0400 632.0000 1.0000
15.0800 566.0000 1.0000
15.1200 589.0000 1.0000
15.1600 601.0000 1.0000
15.2000 605.0000 1.0000
15.2400 595.0000 1.0000
15.2800 572.0000 1.0000
15.3200 578.0000 1.0000
15.3600 641.0000 1.0000
15.4000 609.0000 1.0000
15.4400 622.0000 1.0000
15.4800 608.0000 1.0000
15.5200 617.0000 1.0000
15.5600 647.0000 1.0000
15.6000 611.0000 1.0000
15.6400 615.0000 1.0000
15.6800 613.0000 1.0000
15.7200 618.0000 1.0000
15.7600 620.0000 1.0000
15.8000 608.0000 1.0000
15.8400 614.0000 1.0000
15.8800 645.0000 1.0000
15.9200 620.0000 1.0000
15.9600 616.0000 1.0000
16.0000 625.0000 1.0000
16.0400 621.0000 1.0000
16.0800 639.0000 1.0000
16.1200 653.0000 1.0000
16.1600 631.0000 1.0000
16.2000 652.0000 1.0000
16.2400 652.0000 1.0000
16.2800 626.0000 1.0000
16.3200 660.0000 1.0000
16.3600 666.0000 1.0000
16.4000 669.0000 1.0000
16.4400 644.0000 1.0000
16.4800 641.0000 1.0000
16.5200 623.0000 1.0000
16.5600 648.0000 1.0000
16.6000 660.0000 1.0000
16.6400 617.0000 1.0000
16.6800 651.0000 1.0000
16.7200 625.0000 1.0000
16.7600 663.0000 1.0000
16.8000 660.0000 1.0000
16.8400 671.0000 1.0000
16.8800 676.0000 1.0000
16.9200 632.0000 1.0000
16.9600 650.0000 1.0000
17.0000 665.0000 1.0000
17.0400 641.0000 1.0000
17.0800 666.0000 1.0000
17.1200 679.0000 1.0000
17.1600 675.0000 1.0000
17.2000 674.0000 1.0000
17.2400 678.0000 1.0000
17.2800 706.0000 1.0000
17.3200 710.0000 1.0000
17.3600 679.0000 1.0000
17.4000 686.0000 1.0000
17.4400 666.0000 1.0000
17.4800 684.0000 1.0000
17.5200 662.0000 1.0000
17.5600 688.0000 1.0000
17.6000 724.0000 1.0000
17.6400 708.0000 1.0000
17.6800 680.0000 1.0000
17.7200 706.0000 1.0000
17.7600 724.0000 1.0000
17.8000 715.0000 1.0000
17.8400 716.0000 1.0000
17.8800 701.0000 1.0000
17.9200 754.0000 1.0000
17.9600 719.0000 1.0000
18.0000 739.0000 1.0000
18.0400 707.0000 1.0000
18.0800 765.0000 1.0000
18.1200 732.0000 1.0000
18.1600 761.0000 1.0000
18.2000 739.0000 1.0000
18.2400 754.0000 1.0000
18.2800 761.0000 1.0000
18.3200 769.0000 1.0000
18.3600 777.0000 1.0000
18.4000 776.0000 1.0000
18.4400 783.0000 1.0000
18.4800 797.0000 1.0000
18.5200 767.0000 1.0000
18.5600 774.0000 1.0000
18.6000 785.0000 1.0000
18.6400 828.0000 1.0000
18.6800 799.0000 1.0000
18.7200 801.0000 1.0000
18.7600 797.0000 1.0000
18.8000 829.0000 1.0000
18.8400 833.0000 1.0000
18.8800 799.0000 1.0000
18.9200 812.0000 1.0000
18.9600 845.0000 1.0000
19.0000 862.0000 1.0000
19.0400 855.0000 1.0000
19.0800 879.0000 1.0000
19.1200 828.0000 1.0000
19.1600 863.0000 1.0000
19.2000 882.0000 1.0000
19.2400 848.0000 1.0000
19.2800 876.0000 1.0000
19.3200 926.0000 1.0000
19.3600 893.0000 1.0000
19.4000 950.0000 1.0000
19.4400 946.0000 1.0000
19.4800 988.0000 1.0000
19.5200 967.0000 1.0000
19.5600 997.0000 1.0000
19.6000 988.0000 1.0000
19.6400 1030.0000 1.0000
19.6800 1088.0000 1.0000
19.7200 1018.0000 1.0000
19.7600 1054.0000 1.0000
19.8000 1115.0000 1.0000
19.8400 1101.0000 1.0000
19.8800 1140.0000 1.0000
19.9200 1120.0000 1.0000
19.9600 1165.0000 1.0000
20.0000 1158.0000 1.0000
20.0400 1221.0000 1.0000
20.0800 1150.0000 1.0000
20.1200 1208.0000 1.0000
20.1600 1208.0000 1.0000
20.2000 1210.0000 1.0000
20.2400 1192.0000 1.0000
20.2800 1211.0000 1.0000
20.3200 1235.0000 1.0000
20.3600 1172.0000 1.0000
20.4000 1185.0000 1.0000
20.4400 1172.0000 1.0000
20.4800 1139.0000 1.0000
20.5200 1167.0000 1.0000
20.5600 1159.0000 1.0000
20.6000 1220.0000 1.0000
20.6400 1097.0000 1.0000
20.6800 1094.0000 1.0000
20.7200 1071.0000 1.0000
20.7600 1138.0000 1.0000
20.8000 1066.0000 1.0000
20.8400 1084.0000 1.0000
20.8800 1124.0000 1.0000
20.9200 1065.0000 1.0000
20.9600 1083.0000 1.0000
21.0000 1080.0000 1.0000
21.0400 1098.0000 1.0000
21.0800 1093.0000 1.0000
21.1200 1080.0000 1.0000
21.1600 1082.0000 1.0000
21.2000 1087.0000 1.0000
21.2400 1130.0000 1.0000
21.2800 1076.0000 1.0000
21.3200 1098.0000 1.0000
21.3600 1130.0000 1.0000
21.4000 1122.0000 1.0000
21.4400 1135.0000 1.0000
21.4800 1096.0000 1.0000
21.5200 1122.0000 1.0000
21.5600 1128.0000 1.0000
21.6000 1128.0000 1.0000
21.6400 1150.0000 1.0000
21.6800 1149.0000 1.0000
21.7200 1110.0000 1.0000
21.7600 1126.0000 1.0000
21.8000 1185.0000 1.0000
21.8400 1149.0000 1.0000
21.8800 1152.0000 1.0000
21.9200 1125.0000 1.0000
21.9600 1114.0000 1.0000
22.0000 1152.0000 1.0000
22.0400 1121.0000 1.0000
22.0800 1119.0000 1.0000
22.1200 1118.0000 1.0000
22.1600 1087.0000 1.0000
22.2000 1058.0000 1.0000
22.2400 1112.0000 1.0000
22.2800 1089.0000 1.0000
22.3200 1103.0000 1.0000
22.3600 1019.0000 1.0000
22.4000 1043.0000 1.0000
22.4400 1025.0000 1.0000
22.4800 1048.0000 1.0000
22.5200 1005.0000 1.0000
22.5600 976.0000 1.0000
22.6000 987.0000 1.0000
22.6400 958.0000 1.0000
22.6800 944.0000 1.0000
22.7200 996.0000 1.0000
22.7600 965.0000 1.0000
22.8000 923.0000 1.0000
22.8400 931.0000 1.0000
22.8800 967.0000 1.0000
22.9200 913.0000 1.0000
22.9600 930.0000 1.0000
23.0000 906.0000 1.0000
23.0400 869.0000 1.0000
23.0800 889.0000 1.0000
23.1200 885.0000 1.0000
23.1600 821.0000 1.0000
23.2000 808.0000 1.0000
23.2400 848.0000 1.0000
23.2800 835.0000 1.0000
23.3200 835.0000 1.0000
23.3600 856.0000 1.0000
23.4000 830.0000 1.0000
23.4400 793.0000 1.0000
23.4800 812.0000 1.0000
23.5200 818.0000 1.0000
23.5600 800.0000 1.0000
23.6000 772.0000 1.0000
23.6400 803.0000 1.0000
23.6800 810.0000 1.0000
23.7200 785.0000 1.0000
23.7600 793.0000 1.0000
23.8000 762.0000 1.0000
23.8400 731.0000 1.0000
23.8800 771.0000 1.0000
23.9200 723.0000 1.0000
23.9600 805.0000 1.0000
24.0000 755.0000 1.0000
24.0400 741.0000 1.0000
24.0800 742.0000 1.0000
24.1200 737.0000 1.0000
24.1600 749.0000 1.0000
24.2000 711.0000 1.0000
24.2400 725.0000 1.0000
24.2800 720.0000 1.0000
24.3200 717.0000 1.0000
24.3600 682.0000 1.0000
24.4000 720.0000 1.0000
24.4400 706.0000 1.0000
24.4800 698.0000 1.0000
24.5200 724.0000 1.0000
24.5600 691.0000 1.0000
24.6000 693.0000 1.0000
24.6400 686.0000 1.0000
24.6800 707.0000 1.0000
24.7200 737.0000 1.0000
24.7600 698.0000 1.0000
24.8000 711.0000 1.0000
24.8400 668.0000 1.0000
24.8800 666.0000 1.0000
24.9200 658.0000 1.0000
24.9600 686.0000 1.0000
25.0000 711.0000 1.0000
25.0400 646.0000 1.0000
25.0800 662.0000 1.0000
25.1200 657.0000 1.0000
25.1600 683.0000 1.0000
25.2000 679.0000 1.0000
25.2400 670.0000 1.0000
25.2800 670.0000 1.0000
25.3200 665.0000 1.0000
25.3600 668.0000 1.0000
25.4000 646.0000 1.0000
25.4400 651.0000 1.0000
25.4800 664.0000 1.0000
25.5200 644.0000 1.0000
25.5600 650.0000 1.0000
25.6000 644.0000 1.0000
25.6400 637.0000 1.0000
25.6800 638.0000 1.0000
25.7200 639.0000 1.0000
25.7600 686.0000 1.0000
25.8000 668.0000 1.0000
25.8400 666.0000 1.0000
25.8800 640.0000 1.0000
25.9200 647.0000 1.0000
25.9600 641.0000 1.0000
26.0000 601.0000 1.0000
26.0400 638.0000 1.0000
26.0800 648.0000 1.0000
26.1200 625.0000 1.0000
26.1600 637.0000 1.0000
26.2000 613.0000 1.0000
26.2400 623.0000 1.0000
26.2800 588.0000 1.0000
26.3200 635.0000 1.0000
26.3600 640.0000 1.0000
26.4000 616.0000 1.0000
26.4400 647.0000 1.0000
26.4800 644.0000 1.0000
26.5200 631.0000 1.0000
26.5600 652.0000 1.0000
26.6000 651.0000 1.0000
26.6400 606.0000 1.0000
26.6800 596.0000 1.0000
26.7200 621.0000 1.0000
26.7600 646.0000 1.0000
26.8000 591.0000 1.0000
26.8400 611.0000 1.0000
26.8800 617.0000 1.0000
26.9200 618.0000 1.0000
26.9600 594.0000 1.0000
27.0000 608.0000 1.0000
27.0400 622.0000 1.0000
27.0800 610.0000 1.0000
27.1200 588.0000 1.0000
27.1600 602.0000 1.0000
27.2000 602.0000 1.0000
27.2400 587.0000 1.0000
27.2800 580.0000 1.0000
27.3200 607.0000 1.0000
27.3600 579.0000 1.0000
27.4000 578.0000 1.0000
27.4400 609.0000 1.0000
27.4800 589.0000 1.0000
27.5200 588.0000 1.0000
27.5600 616.0000 1.0000
27.6000 602.0000 1.0000
27.6400 563.0000 1.0000
27.6800 591.0000 1.0000
27.7200 601.0000 1.0000
27.7600 570.0000 1.0000
27.8000 549.0000 1.0000
27.8400 576.0000 1.0000
27.8800 593.0000 1.0000
27.9200 568.0000 1.0000
27.9600 576.0000 1.0000
28.0000 577.0000 1.0000
28.0400 582.0000 1.0000
28.0800 580.0000 1.0000
28.1200 577.0000 1.0000
28.1600 578.0000 1.0000
28.2000 595.0000 1.0000
28.2400 551.0000 1.0000
28.2800 572.0000 1.0000
28.3200 571.0000 1.0000
28.3600 557.0000 1.0000
28.4000 568.0000 1.0000
28.4400 597.0000 1.0000
28.4800 588.0000 1.0000
28.5200 530.0000 1.0000
28.5600 564.0000 1.0000
28.6000 577.0000 1.0000
28.6400 581.0000 1.0000
28.6800 570.0000 1.0000
28.7200 561.0000 1.0000
28.7600 572.0000 1.0000
28.8000 604.0000 1.0000
28.8400 556.0000 1.0000
28.8800 583.0000 1.0000
28.9200 566.0000 1.0000
28.9600 560.0000 1.0000
29.0000 558.0000 1.0000
29.0400 570.0000 1.0000
29.0800 578.0000 1.0000
29.1200 565.0000 1.0000
29.1600 578.0000 1.0000
29.2000 560.0000 1.0000
29.2400 547.0000 1.0000
29.2800 525.0000 1.0000
29.3200 557.0000 1.0000
29.3600 521.0000 1.0000
29.4000 557.0000 1.0000
29.4400 526.0000 1.0000
29.4800 558.0000 1.0000
29.5200 541.0000 1.0000
29.5600 549.0000 1.0000
29.6000 534.0000 1.0000
29.6400 561.0000 1.0000
29.6800 552.0000 1.0000
29.7200 541.0000 1.0000
29.7600 553.0000 1.0000
29.8000 540.0000 1.0000
29.8400 528.0000 1.0000
29.8800 571.0000 1.0000
29.9200 527.0000 1.0000
29.9600 530.0000 1.0000
30.0000 520.0000 1.0000
30.0400 545.0000 1.0000
30.0800 544.0000 1.0000
30.1200 530.0000 1.0000
30.1600 529.0000 1.0000
30.2000 525.0000 1.0000
30.2400 515.0000 1.0000
30.2800 501.0000 1.0000
30.3200 530.0000 1.0000
30.3600 520.0000 1.0000
30.4000 523.0000 1.0000
30.4400 503.0000 1.0000
30.4800 550.0000 1.0000
30.5200 548.0000 1.0000
30.5600 542.0000 1.0000
30.6000 520.0000 1.0000
30.6400 532.0000 1.0000
30.6800 525.0000 1.0000
30.7200 506.0000 1.0000
30.7600 518.0000 1.0000
30.8000 525.0000 1.0000
30.8400 505.0000 1.0000
30.8800 535.0000 1.0000
30.9200 541.0000 1.0000
30.9600 497.0000 1.0000
31.0000 488.0000 1.0000
31.0400 499.0000 1.0000
31.0800 518.0000 1.0000
31.1200 484.0000 1.0000
31.1600 497.0000 1.0000
31.2000 533.0000 1.0000
31.2400 527.0000 1.0000
31.2800 494.0000 1.0000
31.3200 463.0000 1.0000
31.3600 498.0000 1.0000
31.4000 498.0000 1.0000
31.4400 505.0000 1.0000
31.4800 475.0000 1.0000
31.5200 481.0000 1.0000
31.5600 516.0000 1.0000
31.6000 495.0000 1.0000
31.6400 495.0000 1.0000
31.6800 487.0000 1.0000
31.7200 498.0000 1.0000
31.7600 503.0000 1.0000
31.8000 498.0000 1.0000
31.8400 486.0000 1.0000
31.8800 481.0000 1.0000
31.9200 458.0000 1.0000
31.9600 483.0000 1.0000
32.0000 526.0000 1.0000
32.0400 467.0000 1.0000
32.0800 482.0000 1.0000
32.1200 489.0000 1.0000
32.1600 486.0000 1.0000
32.2000 471.0000 1.0000
32.2400 466.0000 1.0000
32.2800 478.0000 1.0000
32.3200 522.0000 1.0000
32.3600 488.0000 1.0000
32.4000 473.0000 1.0000
32.4400 485.0000 1.0000
32.4800 500.0000 1.0000
32.5200 483.0000 1.0000
32.5600 488.0000 1.0000
32.6000 485.0000 1.0000
32.6400 494.0000 1.0000
32.6800 498.0000 1.0000
32.7200 469.0000 1.0000
32.7600 490.0000 1.0000
32.8000 503.0000 1.0000
32.8400 507.0000 1.0000
32.8800 501.0000 1.0000
32.9200 507.0000 1.0000
32.9600 473.0000 1.0000
33.0000 471.0000 1.0000
33.0400 502.0000 1.0000
33.0800 532.0000 1.0000
33.1200 493.0000 1.0000
33.1600 503.0000 1.0000
33.2000 468.0000 1.0000
33.2400 522.0000 1.0000
33.2800 509.0000 1.0000
33.3200 506.0000 1.0000
33.3600 504.0000 1.0000
33.4000 520.0000 1.0000
33.4400 496.0000 1.0000
33.4800 482.0000 1.0000
33.5200 485.0000 1.0000
33.5600 506.0000 1.0000
33.6000 507.0000 1.0000
33.6400 503.0000 1.0000
33.6800 530.0000 1.0000
33.7200 495.0000 1.0000
33.7600 511.0000 1.0000
33.8000 552.0000 1.0000
33.8400 550.0000 1.0000
33.8800 534.0000 1.0000
33.9200 535.0000 1.0000
33.9600 551.0000 1.0000
34.0000 506.0000 1.0000
34.0400 562.0000 1.0000
34.0800 546.0000 1.0000
34.1200 526.0000 1.0000
34.1600 533.0000 1.0000
34.2000 548.0000 1.0000
34.2400 561.0000 1.0000
34.2800 535.0000 1.0000
34.3200 545.0000 1.0000
34.3600 553.0000 1.0000
34.4000 523.0000 1.0000
34.4400 565.0000 1.0000
34.4800 565.0000 1.0000
34.5200 545.0000 1.0000
34.5600 558.0000 1.0000
34.6000 523.0000 1.0000
34.6400 566.0000 1.0000
34.6800 553.0000 1.0000
34.7200 559.0000 1.0000
34.7600 571.0000 1.0000
34.8000 558.0000 1.0000
34.8400 538.0000 1.0000
34.8800 551.0000 1.0000
34.9200 545.0000 1.0000
34.9600 566.0000 1.0000
35.0000 532.0000 1.0000
35.0400 559.0000 1.0000
35.0800 570.0000 1.0000
35.1200 545.0000 1.0000
35.1600 589.0000 1.0000
35.2000 557.0000 1.0000
35.2400 558.0000 1.0000
35.2800 554.0000 1.0000
35.3200 546.0000 1.0000
35.3600 525.0000 1.0000
35.4000 556.0000 1.0000
35.4400 555.0000 1.0000
35.4800 566.0000 1.0000
35.5200 580.0000 1.0000
35.5600 562.0000 1.0000
35.6000 552.0000 1.0000
35.6400 560.0000 1.0000
35.6800 581.0000 1.0000
35.7200 582.0000 1.0000
35.7600 547.0000 1.0000
35.8000 536.0000 1.0000
35.8400 600.0000 1.0000
35.8800 589.0000 1.0000
35.9200 537.0000 1.0000
35.9600 565.0000 1.0000
36.0000 560.0000 1.0000
36.0400 550.0000 1.0000
36.0800 554.0000 1.0000
36.1200 543.0000 1.0000
36.1600 567.0000 1.0000
36.2000 553.0000 1.0000
36.2400 565.0000 1.0000
36.2800 572.0000 1.0000
36.3200 559.0000 1.0000
36.3600 585.0000 1.0000
36.4000 562.0000 1.0000
36.4400 533.0000 1.0000
36.4800 561.0000 1.0000
36.5200 577.0000 1.0000
36.5600 575.0000 1.0000
36.6000 585.0000 1.0000
36.6400 579.0000 1.0000
36.6800 557.0000 1.0000
36.7200 537.0000 1.0000
36.7600 555.0000 1.0000
36.8000 573.0000 1.0000
36.8400 536.0000 1.0000
36.8800 571.0000 1.0000
36.9200 546.0000 1.0000
36.9600 564.0000 1.0000
37.0000 552.0000 1.0000
37.0400 566.0000 1.0000
37.0800 548.0000 1.0000
37.1200 564.0000 1.0000
37.1600 551.0000 1.0000
37.2000 568.0000 1.0000
37.2400 564.0000 1.0000
37.2800 569.0000 1.0000
37.3200 575.0000 1.0000
37.3600 593.0000 1.0000
37.4000 570.0000 1.0000
37.4400 558.0000 1.0000
37.4800 582.0000 1.0000
37.5200 564.0000 1.0000
37.5600 554.0000 1.0000
37.6000 562.0000 1.0000
37.6400 550.0000 1.0000
37.6800 537.0000 1.0000
37.7200 543.0000 1.0000
37.7600 573.0000 1.0000
37.8000 545.0000 1.0000
37.8400 550.0000 1.0000
37.8800 557.0000 1.0000
37.9200 586.0000 1.0000
37.9600 566.0000 1.0000
38.0000 554.0000 1.0000
38.0400 583.0000 1.0000
38.0800 564.0000 1.0000
38.1200 554.0000 1.0000
38.1600 582.0000 1.0000
38.2000 549.0000 1.0000
38.2400 556.0000 1.0000
38.2800 575.0000 1.0000
38.3200 553.0000 1.0000
38.3600 538.0000 1.0000
38.4000 559.0000 1.0000
38.4400 562.0000 1.0000
38.4800 551.0000 1.0000
38.5200 563.0000 1.0000
38.5600 566.0000 1.0000
38.6000 550.0000 1.0000
38.6400 554.0000 1.0000
38.6800 534.0000 1.0000
38.7200 563.0000 1.0000
38.7600 565.0000 1.0000
38.8000 551.0000 1.0000
38.8400 553.0000 1.0000
38.8800 541.0000 1.0000
38.9200 524.0000 1.0000
38.9600 561.0000 1.0000
39.0000 531.0000 1.0000
39.0400 540.0000 1.0000
39.0800 572.0000 1.0000
39.1200 537.0000 1.0000
39.1600 557.0000 1.0000
39.2000 548.0000 1.0000
39.2400 562.0000 1.0000
39.2800 550.0000 1.0000
39.3200 548.0000 1.0000
39.3600 524.0000 1.0000
39.4000 551.0000 1.0000
39.4400 549.0000 1.0000
39.4800 534.0000 1.0000
39.5200 561.0000 1.0000
39.5600 533.0000 1.0000
39.6000 535.0000 1.0000
39.6400 528.0000 1.0000
39.6800 527.0000 1.0000
39.7200 538.0000 1.0000
39.7600 538.0000 1.0000
39.8000 559.0000 1.0000
39.8400 540.0000 1.0000
39.8800 538.0000 1.0000
39.9200 527.0000 1.0000
39.9600 559.0000 1.0000
40.0000 542.0000 1.0000
40.0400 553.0000 1.0000
40.0800 525.0000 1.0000
40.1200 533.0000 1.0000
40.1600 524.0000 1.0000
40.2000 544.0000 1.0000
40.2400 534.0000 1.0000
40.2800 540.0000 1.0000
40.3200 510.0000 1.0000
40.3600 526.0000 1.0000
40.4000 535.0000 1.0000
40.4400 556.0000 1.0000
40.4800 527.0000 1.0000
40.5200 533.0000 1.0000
40.5600 558.0000 1.0000
40.6000 561.0000 1.0000
40.6400 544.0000 1.0000
40.6800 520.0000 1.0000
40.7200 514.0000 1.0000
40.7600 555.0000 1.0000
40.8000 534.0000 1.0000
40.8400 535.0000 1.0000
40.8800 517.0000 1.0000
40.9200 536.0000 1.0000
40.9600 515.0000 1.0000
41.0000 535.0000 1.0000
41.0400 526.0000 1.0000
41.0800 515.0000 1.0000
41.1200 561.0000 1.0000
41.1600 538.0000 1.0000
41.2000 518.0000 1.0000
41.2400 510.0000 1.0000
41.2800 536.0000 1.0000
41.3200 515.0000 1.0000
41.3600 512.0000 1.0000
41.4000 532.0000 1.0000
41.4400 523.0000 1.0000
41.4800 519.0000 1.0000
41.5200 526.0000 1.0000
41.5600 494.0000 1.0000
41.6000 498.0000 1.0000
41.6400 508.0000 1.0000
41.6800 526.0000 1.0000
41.7200 512.0000 1.0000
41.7600 527.0000 1.0000
41.8000 516.0000 1.0000
41.8400 506.0000 1.0000
41.8800 502.0000 1.0000
41.9200 518.0000 1.0000
41.9600 517.0000 1.0000
42.0000 508.0000 1.0000
42.0400 468.0000 1.0000
42.0800 489.0000 1.0000
42.1200 493.0000 1.0000
42.1600 460.0000 1.0000
42.2000 486.0000 1.0000
42.2400 507.0000 1.0000
42.2800 481.0000 1.0000
42.3200 522.0000 1.0000
42.3600 480.0000 1.0000
42.4000 467.0000 1.0000
42.4400 512.0000 1.0000
42.4800 472.0000 1.0000
42.5200 465.0000 1.0000
42.5600 515.0000 1.0000
42.6000 499.0000 1.0000
42.6400 484.0000 1.0000
42.6800 443.0000 1.0000
42.7200 470.0000 1.0000
42.7600 516.0000 1.0000
42.8000 456.0000 1.0000
42.8400 460.0000 1.0000
42.8800 475.0000 1.0000
42.9200 468.0000 1.0000
42.9600 478.0000 1.0000
43.0000 449.0000 1.0000
43.0400 476.0000 1.0000
43.0800 455.0000 1.0000
43.1200 467.0000 1.0000
43.1600 471.0000 1.0000
43.2000 476.0000 1.0000
43.2400 459.0000 1.0000
43.2800 471.0000 1.0000
43.3200 465.0000 1.0000
43.3600 476.0000 1.0000
43.4000 446.0000 1.0000
43.4400 481.0000 1.0000
43.4800 454.0000 1.0000
43.5200 472.0000 1.0000
43.5600 449.0000 1.0000
43.6000 482.0000 1.0000
43.6400 480.0000 1.0000
43.6800 450.0000 1.0000
43.7200 436.0000 1.0000
43.7600 445.0000 1.0000
43.8000 452.0000 1.0000
43.8400 461.0000 1.0000
43.8800 453.0000 1.0000
43.9200 474.0000 1.0000
43.9600 517.0000 1.0000
44.0000 426.0000 1.0000
44.0400 471.0000 1.0000
44.0800 437.0000 1.0000
44.1200 432.0000 1.0000
44.1600 452.0000 1.0000
44.2000 469.0000 1.0000
44.2400 438.0000 1.0000
44.2800 437.0000 1.0000
44.3200 449.0000 1.0000
44.3600 426.0000 1.0000
44.4000 452.0000 1.0000
44.4400 441.0000 1.0000
44.4800 483.0000 1.0000
44.5200 430.0000 1.0000
44.5600 473.0000 1.0000
44.6000 451.0000 1.0000
44.6400 459.0000 1.0000
44.6800 433.0000 1.0000
44.7200 436.0000 1.0000
44.7600 420.0000 1.0000
44.8000 432.0000 1.0000
44.8400 453.0000 1.0000
44.8800 461.0000 1.0000
44.9200 448.0000 1.0000
44.9600 439.0000 1.0000
45.0000 438.0000 1.0000
45.0400 438.0000 1.0000
45.0800 445.0000 1.0000
45.1200 438.0000 1.0000
45.1600 499.0000 1.0000
45.2000 450.0000 1.0000
45.2400 437.0000 1.0000
45.2800 454.0000 1.0000
45.3200 445.0000 1.0000
45.3600 489.0000 1.0000
45.4000 427.0000 1.0000
45.4400 434.0000 1.0000
45.4800 442.0000 1.0000
45.5200 452.0000 1.0000
45.5600 451.0000 1.0000
45.6000 461.0000 1.0000
45.6400 431.0000 1.0000
45.6800 455.0000 1.0000
45.7200 454.0000 1.0000
45.7600 442.0000 1.0000
45.8000 463.0000 1.0000
45.8400 432.0000 1.0000
45.8800 473.0000 1.0000
45.9200 432.0000 1.0000
45.9600 431.0000 1.0000
46.0000 460.0000 1.0000
46.0400 449.0000 1.0000
46.0800 429.0000 1.0000
46.1200 431.0000 1.0000
46.1600 421.0000 1.0000
46.2000 427.0000 1.0000
46.2400 444.0000 1.0000
46.2800 466.0000 1.0000
46.3200 443.0000 1.0000
46.3600 450.0000 1.0000
46.4000 474.0000 1.0000
46.4400 418.0000 1.0000
46.4800 428.0000 1.0000
46.5200 416.0000 1.0000
46.5600 425.0000 1.0000
46.6000 438.0000 1.0000
46.6400 448.0000 1.0000
46.6800 414.0000 1.0000
46.7200 400.0000 1.0000
46.7600 442.0000 1.0000
46.8000 437.0000 1.0000
46.8400 455.0000 1.0000
46.8800 416.0000 1.0000
46.9200 409.0000 1.0000
46.9600 404.0000 1.0000
47.0000 439.0000 1.0000
47.0400 430.0000 1.0000
47.0800 416.0000 1.0000
47.1200 425.0000 1.0000
47.1600 418.0000 1.0000
47.2000 419.0000 1.0000
47.2400 436.0000 1.0000
47.2800 429.0000 1.0000
47.3200 397.0000 1.0000
47.3600 442.0000 1.0000
47.4000 405.0000 1.0000
47.4400 433.0000 1.0000
47.4800 399.0000 1.0000
47.5200 469.0000 1.0000
47.5600 416.0000 1.0000
47.6000 422.0000 1.0000
47.6400 379.0000 1.0000
47.6800 413.0000 1.0000
47.7200 415.0000 1.0000
47.7600 402.0000 1.0000
47.8000 428.0000 1.0000
47.8400 398.0000 1.0000
47.8800 426.0000 1.0000
47.9200 412.0000 1.0000
47.9600 400.0000 1.0000
48.0000 440.0000 1.0000
48.0400 416.0000 1.0000
48.0800 377.0000 1.0000
48.1200 410.0000 1.0000
48.1600 397.0000 1.0000
48.2000 410.0000 1.0000
48.2400 414.0000 1.0000
48.2800 411.0000 1.0000
48.3200 389.0000 1.0000
48.3600 404.0000 1.0000
48.4000 416.0000 1.0000
48.4400 379.0000 1.0000
48.4800 407.0000 1.0000
48.5200 381.0000 1.0000
48.5600 388.0000 1.0000
48.6000 375.0000 1.0000
48.6400 390.0000 1.0000
48.6800 425.0000 1.0000
48.7200 407.0000 1.0000
48.7600 395.0000 1.0000
48.8000 402.0000 1.0000
48.8400 392.0000 1.0000
48.8800 404.0000 1.0000
48.9200 416.0000 1.0000
48.9600 406.0000 1.0000
49.0000 389.0000 1.0000
49.0400 397.0000 1.0000
49.0800 385.0000 1.0000
49.1200 420.0000 1.0000
49.1600 382.0000 1.0000
49.2000 388.0000 1.0000
49.2400 388.0000 1.0000
49.2800 399.0000 1.0000
49.3200 410.0000 1.0000
49.3600 380.0000 1.0000
49.4000 383.0000 1.0000
49.4400 389.0000 1.0000
49.4800 374.0000 1.0000
49.5200 395.0000 1.0000
49.5600 401.0000 1.0000
49.6000 373.0000 1.0000
49.6400 405.0000 1.0000
49.6800 382.0000 1.0000
49.7200 382.0000 1.0000
49.7600 392.0000 1.0000
49.8000 373.0000 1.0000
49.8400 386.0000 1.0000
49.8800 385.0000 1.0000
49.9200 415.0000 1.0000
49.9600 376.0000 1.0000
50.0000 350.0000 1.0000
50.0400 367.0000 1.0000
50.0800 369.0000 1.0000
50.1200 365.0000 1.0000
50.1600 350.0000 1.0000
50.2000 385.0000 1.0000
50.2400 397.0000 1.0000
50.2800 371.0000 1.0000
50.3200 367.0000 1.0000
50.3600 371.0000 1.0000
50.4000 361.0000 1.0000
50.4400 369.0000 1.0000
50.4800 362.0000 1.0000
50.5200 383.0000 1.0000
50.5600 378.0000 1.0000
50.6000 371.0000 1.0000
50.6400 357.0000 1.0000
50.6800 371.0000 1.0000
50.7200 347.0000 1.0000
50.7600 351.0000 1.0000
50.8000 338.0000 1.0000
50.8400 377.0000 1.0000
50.8800 365.0000 1.0000
50.9200 349.0000 1.0000
50.9600 364.0000 1.0000
51.0000 347.0000 1.0000
51.0400 375.0000 1.0000
51.0800 381.0000 1.0000
51.1200 362.0000 1.0000
51.1600 354.0000 1.0000
51.2000 347.0000 1.0000
51.2400 351.0000 1.0000
51.2800 350.0000 1.0000
51.3200 351.0000 1.0000
51.3600 363.0000 1.0000
51.4000 367.0000 1.0000
51.4400 362.0000 1.0000
51.4800 354.0000 1.0000
51.5200 370.0000 1.0000
51.5600 342.0000 1.0000
51.6000 349.0000 1.0000
51.6400 370.0000 1.0000
51.6800 336.0000 1.0000
51.7200 331.0000 1.0000
51.7600 361.0000 1.0000
51.8000 331.0000 1.0000
51.8400 361.0000 1.0000
51.8800 342.0000 1.0000
51.9200 351.0000 1.0000
51.9600 342.0000 1.0000
52.0000 347.0000 1.0000
52.0400 362.0000 1.0000
52.0800 350.0000 1.0000
52.1200 346.0000 1.0000
52.1600 335.0000 1.0000
52.2000 359.0000 1.0000
52.2400 316.0000 1.0000
52.2800 347.0000 1.0000
52.3200 350.0000 1.0000
52.3600 330.0000 1.0000
52.4000 339.0000 1.0000
52.4400 332.0000 1.0000
52.4800 330.0000 1.0000
52.5200 349.0000 1.0000
52.5600 323.0000 1.0000
52.6000 324.0000 1.0000
52.6400 336.0000 1.0000
52.6800 321.0000 1.0000
52.7200 338.0000 1.0000
52.7600 324.0000 1.0000
52.8000 345.0000 1.0000
52.8400 350.0000 1.0000
52.8800 340.0000 1.0000
52.9200 333.0000 1.0000
52.9600 336.0000 1.0000
53.0000 325.0000 1.0000
53.0400 303.0000 1.0000
53.0800 339.0000 1.0000
53.1200 327.0000 1.0000
53.1600 336.0000 1.0000
53.2000 342.0000 1.0000
53.2400 330.0000 1.0000
53.2800 320.0000 1.0000
53.3200 343.0000 1.0000
53.3600 317.0000 1.0000
53.4000 355.0000 1.0000
53.4400 330.0000 1.0000
53.4800 310.0000 1.0000
53.5200 314.0000 1.0000
53.5600 325.0000 1.0000
53.6000 324.0000 1.0000
53.6400 350.0000 1.0000
53.6800 319.0000 1.0000
53.7200 335.0000 1.0000
53.7600 295.0000 1.0000
53.8000 348.0000 1.0000
53.8400 335.0000 1.0000
53.8800 313.0000 1.0000
53.9200 333.0000 1.0000
53.9600 318.0000 1.0000
54.0000 342.0000 1.0000
54.0400 337.0000 1.0000
54.0800 322.0000 1.0000
54.1200 318.0000 1.0000
54.1600 297.0000 1.0000
54.2000 329.0000 1.0000
54.2400 317.0000 1.0000
54.2800 328.0000 1.0000
54.3200 323.0000 1.0000
54.3600 329.0000 1.0000
54.4000 339.0000 1.0000
54.4400 338.0000 1.0000
54.4800 330.0000 1.0000
54.5200 325.0000 1.0000
54.5600 353.0000 1.0000
54.6000 335.0000 1.0000
54.6400 322.0000 1.0000
54.6800 335.0000 1.0000
54.7200 312.0000 1.0000
54.7600 321.0000 1.0000
54.8000 318.0000 1.0000
54.8400 308.0000 1.0000
54.8800 305.0000 1.0000
54.9200 300.0000 1.0000
54.9600 310.0000 1.0000
55.0000 314.0000 1.0000
55.0400 317.0000 1.0000
55.0800 316.0000 1.0000
55.1200 322.0000 1.0000
55.1600 307.0000 1.0000
55.2000 310.0000 1.0000
55.2400 324.0000 1.0000
55.2800 329.0000 1.0000
55.3200 341.0000 1.0000
55.3600 341.0000 1.0000
55.4000 289.0000 1.0000
55.4400 304.0000 1.0000
55.4800 346.0000 1.0000
55.5200 311.0000 1.0000
55.5600 317.0000 1.0000
55.6000 324.0000 1.0000
55.6400 318.0000 1.0000
55.6800 317.0000 1.0000
55.7200 308.0000 1.0000
55.7600 325.0000 1.0000
55.8000 309.0000 1.0000
55.8400 315.0000 1.0000
55.8800 304.0000 1.0000
55.9200 324.0000 1.0000
55.9600 317.0000 1.0000
56.0000 320.0000 1.0000
56.0400 324.0000 1.0000
56.0800 332.0000 1.0000
56.1200 321.0000 1.0000
56.1600 278.0000 1.0000
56.2000 302.0000 1.0000
56.2400 296.0000 1.0000
56.2800 287.0000 1.0000
56.3200 304.0000 1.0000
56.3600 310.0000 1.0000
56.4000 314.0000 1.0000
56.4400 318.0000 1.0000
56.4800 309.0000 1.0000
56.5200 303.0000 1.0000
56.5600 329.0000 1.0000
56.6000 326.0000 1.0000
56.6400 298.0000 1.0000
56.6800 296.0000 1.0000
56.7200 276.0000 1.0000
56.7600 301.0000 1.0000
56.8000 306.0000 1.0000
56.8400 292.0000 1.0000
56.8800 305.0000 1.0000
56.9200 314.0000 1.0000
56.9600 310.0000 1.0000
57.0000 303.0000 1.0000
57.0400 290.0000 1.0000
57.0800 305.0000 1.0000
57.1200 290.0000 1.0000
57.1600 284.0000 1.0000
57.2000 298.0000 1.0000
57.2400 307.0000 1.0000
57.2800 312.0000 1.0000
57.3200 305.0000 1.0000
57.3600 296.0000 1.0000
57.4000 311.0000 1.0000
57.4400 313.0000 1.0000
57.4800 276.0000 1.0000
57.5200 310.0000 1.0000
57.5600 279.0000 1.0000
57.6000 287.0000 1.0000
57.6400 302.0000 1.0000
57.6800 299.0000 1.0000
57.7200 290.0000 1.0000
57.7600 298.0000 1.0000
57.8000 286.0000 1.0000
57.8400 285.0000 1.0000
57.8800 294.0000 1.0000
57.9200 299.0000 1.0000
57.9600 304.0000 1.0000
58.0000 298.0000 1.0000
58.0400 292.0000 1.0000
58.0800 298.0000 1.0000
58.1200 286.0000 1.0000
58.1600 290.0000 1.0000
58.2000 295.0000 1.0000
58.2400 288.0000 1.0000
58.2800 299.0000 1.0000
58.3200 288.0000 1.0000
58.3600 292.0000 1.0000
58.4000 303.0000 1.0000
58.4400 269.0000 1.0000
58.4800 289.0000 1.0000
58.5200 286.0000 1.0000
58.5600 288.0000 1.0000
58.6000 297.0000 1.0000
58.6400 265.0000 1.0000
58.6800 265.0000 1.0000
58.7200 299.0000 1.0000
58.7600 287.0000 1.0000
58.8000 273.0000 1.0000
58.8400 282.0000 1.0000
58.8800 283.0000 1.0000
58.9200 294.0000 1.0000
58.9600 300.0000 1.0000
59.0000 286.0000 1.0000
59.0400 284.0000 1.0000
59.0800 298.0000 1.0000
59.1200 278.0000 1.0000
59.1600 283.0000 1.0000
59.2000 298.0000 1.0000
59.2400 286.0000 1.0000
59.2800 281.0000 1.0000
59.3200 292.0000 1.0000
59.3600 285.0000 1.0000
59.4000 289.0000 1.0000
59.4400 294.0000 1.0000
59.4800 281.0000 1.0000
59.5200 271.0000 1.0000
59.5600 288.0000 1.0000
59.6000 285.0000 1.0000
59.6400 277.0000 1.0000
59.6800 285.0000 1.0000
59.7200 276.0000 1.0000
59.7600 263.0000 1.0000
59.8000 263.0000 1.0000
59.8400 253.0000 1.0000
59.8800 290.0000 1.0000
59.9200 263.0000 1.0000
59.9600 286.0000 1.0000
60.0000 247.0000 1.0000
*RAS_INT_END
*RAS_DATA_END